2020-07-25 23:46:45,098 - 5566-ERROR-ApiException occurred, args=('A request to the Telegram API was unsuccessful. The server returned HTTP 409 Conflict. Response body:\n[b\'{"ok":false,"error_code":409,"description":"Conflict: terminated by other getUpdates request; make sure that only one bot instance is running"}\']',)
Traceback (most recent call last):
  File "/home/pavel/PycharmProjects/weather_bot/venv/lib/python3.8/site-packages/telebot/util.py", line 62, in run
    task(*args, **kwargs)
  File "/home/pavel/PycharmProjects/weather_bot/venv/lib/python3.8/site-packages/telebot/__init__.py", line 285, in __retrieve_updates
    updates = self.get_updates(offset=(self.last_update_id + 1), timeout=timeout)
  File "/home/pavel/PycharmProjects/weather_bot/venv/lib/python3.8/site-packages/telebot/__init__.py", line 255, in get_updates
    json_updates = apihelper.get_updates(self.token, offset, limit, timeout, allowed_updates)
  File "/home/pavel/PycharmProjects/weather_bot/venv/lib/python3.8/site-packages/telebot/apihelper.py", line 206, in get_updates
    return _make_request(token, method_url, params=payload)
  File "/home/pavel/PycharmProjects/weather_bot/venv/lib/python3.8/site-packages/telebot/apihelper.py", line 69, in _make_request
    return _check_result(method_name, result)['result']
  File "/home/pavel/PycharmProjects/weather_bot/venv/lib/python3.8/site-packages/telebot/apihelper.py", line 88, in _check_result
    raise ApiException(msg, method_name, result)
telebot.apihelper.ApiException: A request to the Telegram API was unsuccessful. The server returned HTTP 409 Conflict. Response body:
[b'{"ok":false,"error_code":409,"description":"Conflict: terminated by other getUpdates request; make sure that only one bot instance is running"}']

2020-07-25 23:46:45,099 - 5566-ERROR-A request to the Telegram API was unsuccessful. The server returned HTTP 409 Conflict. Response body:
[b'{"ok":false,"error_code":409,"description":"Conflict: terminated by other getUpdates request; make sure that only one bot instance is running"}']
2020-07-25 23:47:28,533 - 5566-ERROR-error sending message to 558904418 ('Connection aborted.', OSError(101, 'Network is unreachable'))
2020-07-25 23:47:37,925 - 5566-ERROR-ApiException occurred, args=('A request to the Telegram API was unsuccessful. The server returned HTTP 409 Conflict. Response body:\n[b\'{"ok":false,"error_code":409,"description":"Conflict: terminated by other getUpdates request; make sure that only one bot instance is running"}\']',)
Traceback (most recent call last):
  File "/home/pavel/PycharmProjects/weather_bot/venv/lib/python3.8/site-packages/telebot/util.py", line 62, in run
    task(*args, **kwargs)
  File "/home/pavel/PycharmProjects/weather_bot/venv/lib/python3.8/site-packages/telebot/__init__.py", line 285, in __retrieve_updates
    updates = self.get_updates(offset=(self.last_update_id + 1), timeout=timeout)
  File "/home/pavel/PycharmProjects/weather_bot/venv/lib/python3.8/site-packages/telebot/__init__.py", line 255, in get_updates
    json_updates = apihelper.get_updates(self.token, offset, limit, timeout, allowed_updates)
  File "/home/pavel/PycharmProjects/weather_bot/venv/lib/python3.8/site-packages/telebot/apihelper.py", line 206, in get_updates
    return _make_request(token, method_url, params=payload)
  File "/home/pavel/PycharmProjects/weather_bot/venv/lib/python3.8/site-packages/telebot/apihelper.py", line 69, in _make_request
    return _check_result(method_name, result)['result']
  File "/home/pavel/PycharmProjects/weather_bot/venv/lib/python3.8/site-packages/telebot/apihelper.py", line 88, in _check_result
    raise ApiException(msg, method_name, result)
telebot.apihelper.ApiException: A request to the Telegram API was unsuccessful. The server returned HTTP 409 Conflict. Response body:
[b'{"ok":false,"error_code":409,"description":"Conflict: terminated by other getUpdates request; make sure that only one bot instance is running"}']

2020-07-25 23:47:37,925 - 5566-ERROR-A request to the Telegram API was unsuccessful. The server returned HTTP 409 Conflict. Response body:
[b'{"ok":false,"error_code":409,"description":"Conflict: terminated by other getUpdates request; make sure that only one bot instance is running"}']
2020-07-25 23:47:40,798 - 5566-ERROR-ApiException occurred, args=('A request to the Telegram API was unsuccessful. The server returned HTTP 409 Conflict. Response body:\n[b\'{"ok":false,"error_code":409,"description":"Conflict: terminated by other getUpdates request; make sure that only one bot instance is running"}\']',)
Traceback (most recent call last):
  File "/home/pavel/PycharmProjects/weather_bot/venv/lib/python3.8/site-packages/telebot/util.py", line 62, in run
    task(*args, **kwargs)
  File "/home/pavel/PycharmProjects/weather_bot/venv/lib/python3.8/site-packages/telebot/__init__.py", line 285, in __retrieve_updates
    updates = self.get_updates(offset=(self.last_update_id + 1), timeout=timeout)
  File "/home/pavel/PycharmProjects/weather_bot/venv/lib/python3.8/site-packages/telebot/__init__.py", line 255, in get_updates
    json_updates = apihelper.get_updates(self.token, offset, limit, timeout, allowed_updates)
  File "/home/pavel/PycharmProjects/weather_bot/venv/lib/python3.8/site-packages/telebot/apihelper.py", line 206, in get_updates
    return _make_request(token, method_url, params=payload)
  File "/home/pavel/PycharmProjects/weather_bot/venv/lib/python3.8/site-packages/telebot/apihelper.py", line 69, in _make_request
    return _check_result(method_name, result)['result']
  File "/home/pavel/PycharmProjects/weather_bot/venv/lib/python3.8/site-packages/telebot/apihelper.py", line 88, in _check_result
    raise ApiException(msg, method_name, result)
telebot.apihelper.ApiException: A request to the Telegram API was unsuccessful. The server returned HTTP 409 Conflict. Response body:
[b'{"ok":false,"error_code":409,"description":"Conflict: terminated by other getUpdates request; make sure that only one bot instance is running"}']

2020-07-25 23:47:40,799 - 5566-ERROR-A request to the Telegram API was unsuccessful. The server returned HTTP 409 Conflict. Response body:
[b'{"ok":false,"error_code":409,"description":"Conflict: terminated by other getUpdates request; make sure that only one bot instance is running"}']
2020-07-25 23:47:49,524 - 5566-ERROR-ApiException occurred, args=('A request to the Telegram API was unsuccessful. The server returned HTTP 409 Conflict. Response body:\n[b\'{"ok":false,"error_code":409,"description":"Conflict: terminated by other getUpdates request; make sure that only one bot instance is running"}\']',)
Traceback (most recent call last):
  File "/home/pavel/PycharmProjects/weather_bot/venv/lib/python3.8/site-packages/telebot/util.py", line 62, in run
    task(*args, **kwargs)
  File "/home/pavel/PycharmProjects/weather_bot/venv/lib/python3.8/site-packages/telebot/__init__.py", line 285, in __retrieve_updates
    updates = self.get_updates(offset=(self.last_update_id + 1), timeout=timeout)
  File "/home/pavel/PycharmProjects/weather_bot/venv/lib/python3.8/site-packages/telebot/__init__.py", line 255, in get_updates
    json_updates = apihelper.get_updates(self.token, offset, limit, timeout, allowed_updates)
  File "/home/pavel/PycharmProjects/weather_bot/venv/lib/python3.8/site-packages/telebot/apihelper.py", line 206, in get_updates
    return _make_request(token, method_url, params=payload)
  File "/home/pavel/PycharmProjects/weather_bot/venv/lib/python3.8/site-packages/telebot/apihelper.py", line 69, in _make_request
    return _check_result(method_name, result)['result']
  File "/home/pavel/PycharmProjects/weather_bot/venv/lib/python3.8/site-packages/telebot/apihelper.py", line 88, in _check_result
    raise ApiException(msg, method_name, result)
telebot.apihelper.ApiException: A request to the Telegram API was unsuccessful. The server returned HTTP 409 Conflict. Response body:
[b'{"ok":false,"error_code":409,"description":"Conflict: terminated by other getUpdates request; make sure that only one bot instance is running"}']

2020-07-25 23:47:49,524 - 5566-ERROR-A request to the Telegram API was unsuccessful. The server returned HTTP 409 Conflict. Response body:
[b'{"ok":false,"error_code":409,"description":"Conflict: terminated by other getUpdates request; make sure that only one bot instance is running"}']
2020-07-25 23:47:53,304 - 5566-ERROR-ApiException occurred, args=('A request to the Telegram API was unsuccessful. The server returned HTTP 409 Conflict. Response body:\n[b\'{"ok":false,"error_code":409,"description":"Conflict: terminated by other getUpdates request; make sure that only one bot instance is running"}\']',)
Traceback (most recent call last):
  File "/home/pavel/PycharmProjects/weather_bot/venv/lib/python3.8/site-packages/telebot/util.py", line 62, in run
    task(*args, **kwargs)
  File "/home/pavel/PycharmProjects/weather_bot/venv/lib/python3.8/site-packages/telebot/__init__.py", line 285, in __retrieve_updates
    updates = self.get_updates(offset=(self.last_update_id + 1), timeout=timeout)
  File "/home/pavel/PycharmProjects/weather_bot/venv/lib/python3.8/site-packages/telebot/__init__.py", line 255, in get_updates
    json_updates = apihelper.get_updates(self.token, offset, limit, timeout, allowed_updates)
  File "/home/pavel/PycharmProjects/weather_bot/venv/lib/python3.8/site-packages/telebot/apihelper.py", line 206, in get_updates
    return _make_request(token, method_url, params=payload)
  File "/home/pavel/PycharmProjects/weather_bot/venv/lib/python3.8/site-packages/telebot/apihelper.py", line 69, in _make_request
    return _check_result(method_name, result)['result']
  File "/home/pavel/PycharmProjects/weather_bot/venv/lib/python3.8/site-packages/telebot/apihelper.py", line 88, in _check_result
    raise ApiException(msg, method_name, result)
telebot.apihelper.ApiException: A request to the Telegram API was unsuccessful. The server returned HTTP 409 Conflict. Response body:
[b'{"ok":false,"error_code":409,"description":"Conflict: terminated by other getUpdates request; make sure that only one bot instance is running"}']

2020-07-25 23:47:53,304 - 5566-ERROR-A request to the Telegram API was unsuccessful. The server returned HTTP 409 Conflict. Response body:
[b'{"ok":false,"error_code":409,"description":"Conflict: terminated by other getUpdates request; make sure that only one bot instance is running"}']
2020-07-25 23:47:57,477 - 5566-ERROR-ApiException occurred, args=('A request to the Telegram API was unsuccessful. The server returned HTTP 409 Conflict. Response body:\n[b\'{"ok":false,"error_code":409,"description":"Conflict: terminated by other getUpdates request; make sure that only one bot instance is running"}\']',)
Traceback (most recent call last):
  File "/home/pavel/PycharmProjects/weather_bot/venv/lib/python3.8/site-packages/telebot/util.py", line 62, in run
    task(*args, **kwargs)
  File "/home/pavel/PycharmProjects/weather_bot/venv/lib/python3.8/site-packages/telebot/__init__.py", line 285, in __retrieve_updates
    updates = self.get_updates(offset=(self.last_update_id + 1), timeout=timeout)
  File "/home/pavel/PycharmProjects/weather_bot/venv/lib/python3.8/site-packages/telebot/__init__.py", line 255, in get_updates
    json_updates = apihelper.get_updates(self.token, offset, limit, timeout, allowed_updates)
  File "/home/pavel/PycharmProjects/weather_bot/venv/lib/python3.8/site-packages/telebot/apihelper.py", line 206, in get_updates
    return _make_request(token, method_url, params=payload)
  File "/home/pavel/PycharmProjects/weather_bot/venv/lib/python3.8/site-packages/telebot/apihelper.py", line 69, in _make_request
    return _check_result(method_name, result)['result']
  File "/home/pavel/PycharmProjects/weather_bot/venv/lib/python3.8/site-packages/telebot/apihelper.py", line 88, in _check_result
    raise ApiException(msg, method_name, result)
telebot.apihelper.ApiException: A request to the Telegram API was unsuccessful. The server returned HTTP 409 Conflict. Response body:
[b'{"ok":false,"error_code":409,"description":"Conflict: terminated by other getUpdates request; make sure that only one bot instance is running"}']

2020-07-25 23:47:57,477 - 5566-ERROR-A request to the Telegram API was unsuccessful. The server returned HTTP 409 Conflict. Response body:
[b'{"ok":false,"error_code":409,"description":"Conflict: terminated by other getUpdates request; make sure that only one bot instance is running"}']
2020-07-25 23:48:02,381 - 5566-ERROR-ApiException occurred, args=('A request to the Telegram API was unsuccessful. The server returned HTTP 409 Conflict. Response body:\n[b\'{"ok":false,"error_code":409,"description":"Conflict: terminated by other getUpdates request; make sure that only one bot instance is running"}\']',)
Traceback (most recent call last):
  File "/home/pavel/PycharmProjects/weather_bot/venv/lib/python3.8/site-packages/telebot/util.py", line 62, in run
    task(*args, **kwargs)
  File "/home/pavel/PycharmProjects/weather_bot/venv/lib/python3.8/site-packages/telebot/__init__.py", line 285, in __retrieve_updates
    updates = self.get_updates(offset=(self.last_update_id + 1), timeout=timeout)
  File "/home/pavel/PycharmProjects/weather_bot/venv/lib/python3.8/site-packages/telebot/__init__.py", line 255, in get_updates
    json_updates = apihelper.get_updates(self.token, offset, limit, timeout, allowed_updates)
  File "/home/pavel/PycharmProjects/weather_bot/venv/lib/python3.8/site-packages/telebot/apihelper.py", line 206, in get_updates
    return _make_request(token, method_url, params=payload)
  File "/home/pavel/PycharmProjects/weather_bot/venv/lib/python3.8/site-packages/telebot/apihelper.py", line 69, in _make_request
    return _check_result(method_name, result)['result']
  File "/home/pavel/PycharmProjects/weather_bot/venv/lib/python3.8/site-packages/telebot/apihelper.py", line 88, in _check_result
    raise ApiException(msg, method_name, result)
telebot.apihelper.ApiException: A request to the Telegram API was unsuccessful. The server returned HTTP 409 Conflict. Response body:
[b'{"ok":false,"error_code":409,"description":"Conflict: terminated by other getUpdates request; make sure that only one bot instance is running"}']

2020-07-25 23:48:02,382 - 5566-ERROR-A request to the Telegram API was unsuccessful. The server returned HTTP 409 Conflict. Response body:
[b'{"ok":false,"error_code":409,"description":"Conflict: terminated by other getUpdates request; make sure that only one bot instance is running"}']
2020-07-25 23:48:08,346 - 5566-ERROR-ApiException occurred, args=('A request to the Telegram API was unsuccessful. The server returned HTTP 409 Conflict. Response body:\n[b\'{"ok":false,"error_code":409,"description":"Conflict: terminated by other getUpdates request; make sure that only one bot instance is running"}\']',)
Traceback (most recent call last):
  File "/home/pavel/PycharmProjects/weather_bot/venv/lib/python3.8/site-packages/telebot/util.py", line 62, in run
    task(*args, **kwargs)
  File "/home/pavel/PycharmProjects/weather_bot/venv/lib/python3.8/site-packages/telebot/__init__.py", line 285, in __retrieve_updates
    updates = self.get_updates(offset=(self.last_update_id + 1), timeout=timeout)
  File "/home/pavel/PycharmProjects/weather_bot/venv/lib/python3.8/site-packages/telebot/__init__.py", line 255, in get_updates
    json_updates = apihelper.get_updates(self.token, offset, limit, timeout, allowed_updates)
  File "/home/pavel/PycharmProjects/weather_bot/venv/lib/python3.8/site-packages/telebot/apihelper.py", line 206, in get_updates
    return _make_request(token, method_url, params=payload)
  File "/home/pavel/PycharmProjects/weather_bot/venv/lib/python3.8/site-packages/telebot/apihelper.py", line 69, in _make_request
    return _check_result(method_name, result)['result']
  File "/home/pavel/PycharmProjects/weather_bot/venv/lib/python3.8/site-packages/telebot/apihelper.py", line 88, in _check_result
    raise ApiException(msg, method_name, result)
telebot.apihelper.ApiException: A request to the Telegram API was unsuccessful. The server returned HTTP 409 Conflict. Response body:
[b'{"ok":false,"error_code":409,"description":"Conflict: terminated by other getUpdates request; make sure that only one bot instance is running"}']

2020-07-25 23:48:08,347 - 5566-ERROR-A request to the Telegram API was unsuccessful. The server returned HTTP 409 Conflict. Response body:
[b'{"ok":false,"error_code":409,"description":"Conflict: terminated by other getUpdates request; make sure that only one bot instance is running"}']
2020-07-25 23:48:16,043 - 5566-ERROR-ApiException occurred, args=('A request to the Telegram API was unsuccessful. The server returned HTTP 409 Conflict. Response body:\n[b\'{"ok":false,"error_code":409,"description":"Conflict: terminated by other getUpdates request; make sure that only one bot instance is running"}\']',)
Traceback (most recent call last):
  File "/home/pavel/PycharmProjects/weather_bot/venv/lib/python3.8/site-packages/telebot/util.py", line 62, in run
    task(*args, **kwargs)
  File "/home/pavel/PycharmProjects/weather_bot/venv/lib/python3.8/site-packages/telebot/__init__.py", line 285, in __retrieve_updates
    updates = self.get_updates(offset=(self.last_update_id + 1), timeout=timeout)
  File "/home/pavel/PycharmProjects/weather_bot/venv/lib/python3.8/site-packages/telebot/__init__.py", line 255, in get_updates
    json_updates = apihelper.get_updates(self.token, offset, limit, timeout, allowed_updates)
  File "/home/pavel/PycharmProjects/weather_bot/venv/lib/python3.8/site-packages/telebot/apihelper.py", line 206, in get_updates
    return _make_request(token, method_url, params=payload)
  File "/home/pavel/PycharmProjects/weather_bot/venv/lib/python3.8/site-packages/telebot/apihelper.py", line 69, in _make_request
    return _check_result(method_name, result)['result']
  File "/home/pavel/PycharmProjects/weather_bot/venv/lib/python3.8/site-packages/telebot/apihelper.py", line 88, in _check_result
    raise ApiException(msg, method_name, result)
telebot.apihelper.ApiException: A request to the Telegram API was unsuccessful. The server returned HTTP 409 Conflict. Response body:
[b'{"ok":false,"error_code":409,"description":"Conflict: terminated by other getUpdates request; make sure that only one bot instance is running"}']

2020-07-25 23:48:16,043 - 5566-ERROR-A request to the Telegram API was unsuccessful. The server returned HTTP 409 Conflict. Response body:
[b'{"ok":false,"error_code":409,"description":"Conflict: terminated by other getUpdates request; make sure that only one bot instance is running"}']
2020-07-25 23:48:20,370 - 5566-ERROR-ApiException occurred, args=('A request to the Telegram API was unsuccessful. The server returned HTTP 409 Conflict. Response body:\n[b\'{"ok":false,"error_code":409,"description":"Conflict: terminated by other getUpdates request; make sure that only one bot instance is running"}\']',)
Traceback (most recent call last):
  File "/home/pavel/PycharmProjects/weather_bot/venv/lib/python3.8/site-packages/telebot/util.py", line 62, in run
    task(*args, **kwargs)
  File "/home/pavel/PycharmProjects/weather_bot/venv/lib/python3.8/site-packages/telebot/__init__.py", line 285, in __retrieve_updates
    updates = self.get_updates(offset=(self.last_update_id + 1), timeout=timeout)
  File "/home/pavel/PycharmProjects/weather_bot/venv/lib/python3.8/site-packages/telebot/__init__.py", line 255, in get_updates
    json_updates = apihelper.get_updates(self.token, offset, limit, timeout, allowed_updates)
  File "/home/pavel/PycharmProjects/weather_bot/venv/lib/python3.8/site-packages/telebot/apihelper.py", line 206, in get_updates
    return _make_request(token, method_url, params=payload)
  File "/home/pavel/PycharmProjects/weather_bot/venv/lib/python3.8/site-packages/telebot/apihelper.py", line 69, in _make_request
    return _check_result(method_name, result)['result']
  File "/home/pavel/PycharmProjects/weather_bot/venv/lib/python3.8/site-packages/telebot/apihelper.py", line 88, in _check_result
    raise ApiException(msg, method_name, result)
telebot.apihelper.ApiException: A request to the Telegram API was unsuccessful. The server returned HTTP 409 Conflict. Response body:
[b'{"ok":false,"error_code":409,"description":"Conflict: terminated by other getUpdates request; make sure that only one bot instance is running"}']

2020-07-25 23:48:20,371 - 5566-ERROR-A request to the Telegram API was unsuccessful. The server returned HTTP 409 Conflict. Response body:
[b'{"ok":false,"error_code":409,"description":"Conflict: terminated by other getUpdates request; make sure that only one bot instance is running"}']
2020-07-25 23:48:24,538 - 5566-ERROR-ApiException occurred, args=('A request to the Telegram API was unsuccessful. The server returned HTTP 409 Conflict. Response body:\n[b\'{"ok":false,"error_code":409,"description":"Conflict: terminated by other getUpdates request; make sure that only one bot instance is running"}\']',)
Traceback (most recent call last):
  File "/home/pavel/PycharmProjects/weather_bot/venv/lib/python3.8/site-packages/telebot/util.py", line 62, in run
    task(*args, **kwargs)
  File "/home/pavel/PycharmProjects/weather_bot/venv/lib/python3.8/site-packages/telebot/__init__.py", line 285, in __retrieve_updates
    updates = self.get_updates(offset=(self.last_update_id + 1), timeout=timeout)
  File "/home/pavel/PycharmProjects/weather_bot/venv/lib/python3.8/site-packages/telebot/__init__.py", line 255, in get_updates
    json_updates = apihelper.get_updates(self.token, offset, limit, timeout, allowed_updates)
  File "/home/pavel/PycharmProjects/weather_bot/venv/lib/python3.8/site-packages/telebot/apihelper.py", line 206, in get_updates
    return _make_request(token, method_url, params=payload)
  File "/home/pavel/PycharmProjects/weather_bot/venv/lib/python3.8/site-packages/telebot/apihelper.py", line 69, in _make_request
    return _check_result(method_name, result)['result']
  File "/home/pavel/PycharmProjects/weather_bot/venv/lib/python3.8/site-packages/telebot/apihelper.py", line 88, in _check_result
    raise ApiException(msg, method_name, result)
telebot.apihelper.ApiException: A request to the Telegram API was unsuccessful. The server returned HTTP 409 Conflict. Response body:
[b'{"ok":false,"error_code":409,"description":"Conflict: terminated by other getUpdates request; make sure that only one bot instance is running"}']

2020-07-25 23:48:24,539 - 5566-ERROR-A request to the Telegram API was unsuccessful. The server returned HTTP 409 Conflict. Response body:
[b'{"ok":false,"error_code":409,"description":"Conflict: terminated by other getUpdates request; make sure that only one bot instance is running"}']
2020-07-25 23:48:28,696 - 5566-ERROR-ApiException occurred, args=('A request to the Telegram API was unsuccessful. The server returned HTTP 409 Conflict. Response body:\n[b\'{"ok":false,"error_code":409,"description":"Conflict: terminated by other getUpdates request; make sure that only one bot instance is running"}\']',)
Traceback (most recent call last):
  File "/home/pavel/PycharmProjects/weather_bot/venv/lib/python3.8/site-packages/telebot/util.py", line 62, in run
    task(*args, **kwargs)
  File "/home/pavel/PycharmProjects/weather_bot/venv/lib/python3.8/site-packages/telebot/__init__.py", line 285, in __retrieve_updates
    updates = self.get_updates(offset=(self.last_update_id + 1), timeout=timeout)
  File "/home/pavel/PycharmProjects/weather_bot/venv/lib/python3.8/site-packages/telebot/__init__.py", line 255, in get_updates
    json_updates = apihelper.get_updates(self.token, offset, limit, timeout, allowed_updates)
  File "/home/pavel/PycharmProjects/weather_bot/venv/lib/python3.8/site-packages/telebot/apihelper.py", line 206, in get_updates
    return _make_request(token, method_url, params=payload)
  File "/home/pavel/PycharmProjects/weather_bot/venv/lib/python3.8/site-packages/telebot/apihelper.py", line 69, in _make_request
    return _check_result(method_name, result)['result']
  File "/home/pavel/PycharmProjects/weather_bot/venv/lib/python3.8/site-packages/telebot/apihelper.py", line 88, in _check_result
    raise ApiException(msg, method_name, result)
telebot.apihelper.ApiException: A request to the Telegram API was unsuccessful. The server returned HTTP 409 Conflict. Response body:
[b'{"ok":false,"error_code":409,"description":"Conflict: terminated by other getUpdates request; make sure that only one bot instance is running"}']

2020-07-25 23:48:28,697 - 5566-ERROR-A request to the Telegram API was unsuccessful. The server returned HTTP 409 Conflict. Response body:
[b'{"ok":false,"error_code":409,"description":"Conflict: terminated by other getUpdates request; make sure that only one bot instance is running"}']
2020-07-25 23:48:33,526 - 5566-ERROR-ApiException occurred, args=('A request to the Telegram API was unsuccessful. The server returned HTTP 409 Conflict. Response body:\n[b\'{"ok":false,"error_code":409,"description":"Conflict: terminated by other getUpdates request; make sure that only one bot instance is running"}\']',)
Traceback (most recent call last):
  File "/home/pavel/PycharmProjects/weather_bot/venv/lib/python3.8/site-packages/telebot/util.py", line 62, in run
    task(*args, **kwargs)
  File "/home/pavel/PycharmProjects/weather_bot/venv/lib/python3.8/site-packages/telebot/__init__.py", line 285, in __retrieve_updates
    updates = self.get_updates(offset=(self.last_update_id + 1), timeout=timeout)
  File "/home/pavel/PycharmProjects/weather_bot/venv/lib/python3.8/site-packages/telebot/__init__.py", line 255, in get_updates
    json_updates = apihelper.get_updates(self.token, offset, limit, timeout, allowed_updates)
  File "/home/pavel/PycharmProjects/weather_bot/venv/lib/python3.8/site-packages/telebot/apihelper.py", line 206, in get_updates
    return _make_request(token, method_url, params=payload)
  File "/home/pavel/PycharmProjects/weather_bot/venv/lib/python3.8/site-packages/telebot/apihelper.py", line 69, in _make_request
    return _check_result(method_name, result)['result']
  File "/home/pavel/PycharmProjects/weather_bot/venv/lib/python3.8/site-packages/telebot/apihelper.py", line 88, in _check_result
    raise ApiException(msg, method_name, result)
telebot.apihelper.ApiException: A request to the Telegram API was unsuccessful. The server returned HTTP 409 Conflict. Response body:
[b'{"ok":false,"error_code":409,"description":"Conflict: terminated by other getUpdates request; make sure that only one bot instance is running"}']

2020-07-25 23:48:33,527 - 5566-ERROR-A request to the Telegram API was unsuccessful. The server returned HTTP 409 Conflict. Response body:
[b'{"ok":false,"error_code":409,"description":"Conflict: terminated by other getUpdates request; make sure that only one bot instance is running"}']
2020-07-25 23:48:37,769 - 5566-ERROR-ApiException occurred, args=('A request to the Telegram API was unsuccessful. The server returned HTTP 409 Conflict. Response body:\n[b\'{"ok":false,"error_code":409,"description":"Conflict: terminated by other getUpdates request; make sure that only one bot instance is running"}\']',)
Traceback (most recent call last):
  File "/home/pavel/PycharmProjects/weather_bot/venv/lib/python3.8/site-packages/telebot/util.py", line 62, in run
    task(*args, **kwargs)
  File "/home/pavel/PycharmProjects/weather_bot/venv/lib/python3.8/site-packages/telebot/__init__.py", line 285, in __retrieve_updates
    updates = self.get_updates(offset=(self.last_update_id + 1), timeout=timeout)
  File "/home/pavel/PycharmProjects/weather_bot/venv/lib/python3.8/site-packages/telebot/__init__.py", line 255, in get_updates
    json_updates = apihelper.get_updates(self.token, offset, limit, timeout, allowed_updates)
  File "/home/pavel/PycharmProjects/weather_bot/venv/lib/python3.8/site-packages/telebot/apihelper.py", line 206, in get_updates
    return _make_request(token, method_url, params=payload)
  File "/home/pavel/PycharmProjects/weather_bot/venv/lib/python3.8/site-packages/telebot/apihelper.py", line 69, in _make_request
    return _check_result(method_name, result)['result']
  File "/home/pavel/PycharmProjects/weather_bot/venv/lib/python3.8/site-packages/telebot/apihelper.py", line 88, in _check_result
    raise ApiException(msg, method_name, result)
telebot.apihelper.ApiException: A request to the Telegram API was unsuccessful. The server returned HTTP 409 Conflict. Response body:
[b'{"ok":false,"error_code":409,"description":"Conflict: terminated by other getUpdates request; make sure that only one bot instance is running"}']

2020-07-25 23:48:37,769 - 5566-ERROR-A request to the Telegram API was unsuccessful. The server returned HTTP 409 Conflict. Response body:
[b'{"ok":false,"error_code":409,"description":"Conflict: terminated by other getUpdates request; make sure that only one bot instance is running"}']
2020-07-25 23:48:43,660 - 5566-ERROR-ApiException occurred, args=('A request to the Telegram API was unsuccessful. The server returned HTTP 409 Conflict. Response body:\n[b\'{"ok":false,"error_code":409,"description":"Conflict: terminated by other getUpdates request; make sure that only one bot instance is running"}\']',)
Traceback (most recent call last):
  File "/home/pavel/PycharmProjects/weather_bot/venv/lib/python3.8/site-packages/telebot/util.py", line 62, in run
    task(*args, **kwargs)
  File "/home/pavel/PycharmProjects/weather_bot/venv/lib/python3.8/site-packages/telebot/__init__.py", line 285, in __retrieve_updates
    updates = self.get_updates(offset=(self.last_update_id + 1), timeout=timeout)
  File "/home/pavel/PycharmProjects/weather_bot/venv/lib/python3.8/site-packages/telebot/__init__.py", line 255, in get_updates
    json_updates = apihelper.get_updates(self.token, offset, limit, timeout, allowed_updates)
  File "/home/pavel/PycharmProjects/weather_bot/venv/lib/python3.8/site-packages/telebot/apihelper.py", line 206, in get_updates
    return _make_request(token, method_url, params=payload)
  File "/home/pavel/PycharmProjects/weather_bot/venv/lib/python3.8/site-packages/telebot/apihelper.py", line 69, in _make_request
    return _check_result(method_name, result)['result']
  File "/home/pavel/PycharmProjects/weather_bot/venv/lib/python3.8/site-packages/telebot/apihelper.py", line 88, in _check_result
    raise ApiException(msg, method_name, result)
telebot.apihelper.ApiException: A request to the Telegram API was unsuccessful. The server returned HTTP 409 Conflict. Response body:
[b'{"ok":false,"error_code":409,"description":"Conflict: terminated by other getUpdates request; make sure that only one bot instance is running"}']

2020-07-25 23:48:43,663 - 5566-ERROR-A request to the Telegram API was unsuccessful. The server returned HTTP 409 Conflict. Response body:
[b'{"ok":false,"error_code":409,"description":"Conflict: terminated by other getUpdates request; make sure that only one bot instance is running"}']
2020-07-25 23:48:47,963 - 5566-ERROR-ApiException occurred, args=('A request to the Telegram API was unsuccessful. The server returned HTTP 409 Conflict. Response body:\n[b\'{"ok":false,"error_code":409,"description":"Conflict: terminated by other getUpdates request; make sure that only one bot instance is running"}\']',)
Traceback (most recent call last):
  File "/home/pavel/PycharmProjects/weather_bot/venv/lib/python3.8/site-packages/telebot/util.py", line 62, in run
    task(*args, **kwargs)
  File "/home/pavel/PycharmProjects/weather_bot/venv/lib/python3.8/site-packages/telebot/__init__.py", line 285, in __retrieve_updates
    updates = self.get_updates(offset=(self.last_update_id + 1), timeout=timeout)
  File "/home/pavel/PycharmProjects/weather_bot/venv/lib/python3.8/site-packages/telebot/__init__.py", line 255, in get_updates
    json_updates = apihelper.get_updates(self.token, offset, limit, timeout, allowed_updates)
  File "/home/pavel/PycharmProjects/weather_bot/venv/lib/python3.8/site-packages/telebot/apihelper.py", line 206, in get_updates
    return _make_request(token, method_url, params=payload)
  File "/home/pavel/PycharmProjects/weather_bot/venv/lib/python3.8/site-packages/telebot/apihelper.py", line 69, in _make_request
    return _check_result(method_name, result)['result']
  File "/home/pavel/PycharmProjects/weather_bot/venv/lib/python3.8/site-packages/telebot/apihelper.py", line 88, in _check_result
    raise ApiException(msg, method_name, result)
telebot.apihelper.ApiException: A request to the Telegram API was unsuccessful. The server returned HTTP 409 Conflict. Response body:
[b'{"ok":false,"error_code":409,"description":"Conflict: terminated by other getUpdates request; make sure that only one bot instance is running"}']

2020-07-25 23:48:47,964 - 5566-ERROR-A request to the Telegram API was unsuccessful. The server returned HTTP 409 Conflict. Response body:
[b'{"ok":false,"error_code":409,"description":"Conflict: terminated by other getUpdates request; make sure that only one bot instance is running"}']
2020-07-25 23:48:54,179 - 5566-ERROR-ApiException occurred, args=('A request to the Telegram API was unsuccessful. The server returned HTTP 409 Conflict. Response body:\n[b\'{"ok":false,"error_code":409,"description":"Conflict: terminated by other getUpdates request; make sure that only one bot instance is running"}\']',)
Traceback (most recent call last):
  File "/home/pavel/PycharmProjects/weather_bot/venv/lib/python3.8/site-packages/telebot/util.py", line 62, in run
    task(*args, **kwargs)
  File "/home/pavel/PycharmProjects/weather_bot/venv/lib/python3.8/site-packages/telebot/__init__.py", line 285, in __retrieve_updates
    updates = self.get_updates(offset=(self.last_update_id + 1), timeout=timeout)
  File "/home/pavel/PycharmProjects/weather_bot/venv/lib/python3.8/site-packages/telebot/__init__.py", line 255, in get_updates
    json_updates = apihelper.get_updates(self.token, offset, limit, timeout, allowed_updates)
  File "/home/pavel/PycharmProjects/weather_bot/venv/lib/python3.8/site-packages/telebot/apihelper.py", line 206, in get_updates
    return _make_request(token, method_url, params=payload)
  File "/home/pavel/PycharmProjects/weather_bot/venv/lib/python3.8/site-packages/telebot/apihelper.py", line 69, in _make_request
    return _check_result(method_name, result)['result']
  File "/home/pavel/PycharmProjects/weather_bot/venv/lib/python3.8/site-packages/telebot/apihelper.py", line 88, in _check_result
    raise ApiException(msg, method_name, result)
telebot.apihelper.ApiException: A request to the Telegram API was unsuccessful. The server returned HTTP 409 Conflict. Response body:
[b'{"ok":false,"error_code":409,"description":"Conflict: terminated by other getUpdates request; make sure that only one bot instance is running"}']

